<?xml version="1.0" encoding="utf-8"?>
<!-- This URDF was automatically created by SolidWorks to URDF Exporter! Originally created by Stephen Brawner (brawner@gmail.com) 
     Commit Version: 1.6.0-1-g15f4949  Build Version: 1.6.7594.29634
     For more information, please see http://wiki.ros.org/sw_urdf_exporter -->
<robot xmlns:xacro="http://ros.org/wiki/xacro">

  <xacro:macro name="pgc140">


  <link
    name="pgc140_base_link">
    <inertial>
      <origin
        xyz="-3.9257E-06 -0.00027208 0.037806"
        rpy="0 0 0" />
      <mass
        value="0.34365" />
      <inertia
        ixx="0.00036805"
        ixy="-7.2868E-08"
        ixz="-5.0168E-08"
        iyy="0.0003341"
        iyz="-2.6462E-06"
        izz="0.00022294" />
    </inertial>
    <visual>
      <origin
        xyz="0 0 0"
        rpy="0 0 0" />
      <geometry>
        <mesh
          filename="package://dh_pgc140_urdf/meshes/base_link.STL" />
      </geometry>
      <material
        name="">
        <color
          rgba="1 1 1 1" />
      </material>
    </visual>
    <collision>
      <origin
        xyz="0 0 0"
        rpy="0 0 0" />
      <geometry>
        <mesh
          filename="package://dh_pgc140_urdf/meshes/base_link.STL" />
      </geometry>
    </collision>
  </link>
  <link
    name="finger1_link">
    <inertial>
      <origin
        xyz="0.0030491 -0.0066024 0.0064209"
        rpy="0 0 0" />
      <mass
        value="0.014278" />
      <inertia
        ixx="1.7567E-06"
        ixy="-5.7832E-08"
        ixz="2.6803E-08"
        iyy="2.3034E-06"
        iyz="2.2145E-07"
        izz="1.3354E-06" />
    </inertial>
    <visual>
      <origin
        xyz="0 0 0"
        rpy="0 0 0" />
      <geometry>
        <mesh
          filename="package://dh_pgc140_urdf/meshes/finger1_Link.STL" />
      </geometry>
      <material
        name="">
        <color
          rgba="1 1 1 1" />
      </material>
    </visual>
    <collision>
      <origin
        xyz="0 0 0"
        rpy="0 0 0" />
      <geometry>
        <mesh
          filename="package://dh_pgc140_urdf/meshes/finger1_Link.STL" />
      </geometry>
    </collision>
  </link>
  <joint
    name="finger1_joint"
    type="prismatic">
    <origin
      xyz="0.0132 0.0265 0.093"
      rpy="0 0 -1.5708" />
    <parent
      link="pgc140_base_link" />
    <child
      link="finger1_link" />
    <axis
      xyz="1 0 0" />
    <limit
      lower="0"
      upper="0.025"
      effort="140"
      velocity="1" />
  </joint>
  <link
    name="finger2_link">
    <inertial>
      <origin
        xyz="0.0030491 -0.0066024 0.0064209"
        rpy="0 0 0" />
      <mass
        value="0.014278" />
      <inertia
        ixx="1.7567E-06"
        ixy="-5.7832E-08"
        ixz="2.6803E-08"
        iyy="2.3034E-06"
        iyz="2.2145E-07"
        izz="1.3354E-06" />
    </inertial>
    <visual>
      <origin
        xyz="0 0 0"
        rpy="0 0 0" />
      <geometry>
        <mesh
          filename="package://dh_pgc140_urdf/meshes/finger2_Link.STL" />
      </geometry>
      <material
        name="">
        <color
          rgba="0.79216 0.81961 0.93333 1" />
      </material>
    </visual>
    <collision>
      <origin
        xyz="0 0 0"
        rpy="0 0 0" />
      <geometry>
        <mesh
          filename="package://dh_pgc140_urdf/meshes/finger2_Link.STL" />
      </geometry>
    </collision>
  </link>
  <joint
    name="finger2_joint"
    type="prismatic">
    <origin
      xyz="-0.0132 -0.0265 0.093"
      rpy="0 0 1.5708" />
    <parent
      link="pgc140_base_link" />
    <child
      link="finger2_link" />
    <axis
      xyz="1 0 0" />
    <limit
      lower="0"
      upper="0.025"
      effort="140"
      velocity="1" />
    <mimic
      joint="finger1_joint"
      multiplier="1.0"
      offset="0.0" /> 
  </joint>
  


  <transmission name="finger1_trans">
      <type>transmission_interface/SimpleTransmission</type>
      <joint name="finger1_joint">
          <hardwareInterface>hardware_interface/PositionJointInterface</hardwareInterface>
      </joint>
      <actuator name="finger1_motor">
          <mechanicalReduction>1</mechanicalReduction>
          <hardwareInterface>hardware_interface/PositionJointInterface</hardwareInterface>
      </actuator>
  </transmission>



  <xacro:macro name="mimic_joint_plugin_gazebo" params="name_prefix parent_joint mimic_joint has_pid:=false multiplier:=1.0 offset:=0 sensitiveness:=0.0 max_effort:=1.0 robot_namespace:=''">
    <gazebo>
      <plugin name="${name_prefix}mimic_joint_plugin" filename="libroboticsgroup_gazebo_mimic_joint_plugin.so">
        <joint>${parent_joint}</joint>
        <mimicJoint>${mimic_joint}</mimicJoint>
        <xacro:if value="${has_pid}">                     <!-- if set to true, PID parameters from "/gazebo_ros_control/pid_gains/${mimic_joint}" are loaded -->
          <hasPID />
        </xacro:if>
        <multiplier>${multiplier}</multiplier>
        <offset>${offset}</offset>
        <sensitiveness>${sensitiveness}</sensitiveness>   <!-- if absolute difference between setpoint and process value is below this threshold, do nothing; 0.0 = disable [rad] -->
        <maxEffort>${max_effort}</maxEffort>              <!-- only taken into account if has_pid:=true [Nm] -->
        <xacro:unless value="${robot_namespace == ''}">
          <robotNamespace>${robot_namespace}</robotNamespace>
        </xacro:unless>
      </plugin>
    </gazebo>
  </xacro:macro>

  <xacro:mimic_joint_plugin_gazebo name_prefix="finger2_joint"
    parent_joint="finger1_joint" mimic_joint="finger2_joint"
    has_pid="true" multiplier="1.0" max_effort="10.0" />

<!-- 
  <gazebo>
    <plugin filename="libroboticsgroup_upatras_gazebo_mimic_joint_plugin.so" name="mimicker">
      <joint>finger1_joint</joint>
      <mimicJoint>finger2_joint</mimicJoint>
    </plugin>
  </gazebo> -->

  </xacro:macro>
</robot>
