<?xml version="1.0" encoding="utf-8" ?>
<!-- =================================================================================== -->
<!-- |    This document was autogenerated by xacro from /home/ian/catkin_ws/src/LARA_AUBOi5_AG95/lara_description/urdf/lara_base_scene.xacro | -->
<!-- |    EDITING THIS FILE BY HAND IS NOT RECOMMENDED                                 | -->
<!-- =================================================================================== -->
<robot name="lara_base_scene">
    <material name="wood">
        <color rgba="0.58 0.43 0.2 1.000" />
    </material>
    <material name="aluminum">
        <color rgba="0.121 0.218 0.33 1.000" />
    </material>
    <gazebo reference="arm_mount_1">
        <material>Gazebo/DarkGrey</material>
        <kp>1000000.0</kp>
        <kd>1.0</kd>
        <mu1>0.8</mu1>
        <mu2>0.8</mu2>
        <maxVel>0.0</maxVel>
        <minDepth>0.001</minDepth>
        <selfCollide>true</selfCollide>
        <plugin name="gazebo_ros_control">
            <robotNamespace>/</robotNamespace>
        </plugin>
    </gazebo>
    <gazebo reference="arm_mount_2">
        <material>Gazebo/DarkGrey</material>
        <kp>1000000.0</kp>
        <kd>1.0</kd>
        <mu1>0.8</mu1>
        <mu2>0.8</mu2>
        <maxVel>0.0</maxVel>
        <minDepth>0.001</minDepth>
        <selfCollide>true</selfCollide>
    </gazebo>
    <gazebo reference="base_mount">
        <material>Gazebo/DarkGrey</material>
        <kp>1000000.0</kp>
        <kd>1.0</kd>
        <mu1>0.8</mu1>
        <mu2>0.8</mu2>
        <maxVel>0.0</maxVel>
        <minDepth>0.001</minDepth>
        <selfCollide>true</selfCollide>
    </gazebo>
    <gazebo reference="table">
        <material>Gazebo/Wood</material>
        <kp>1000000.0</kp>
        <kd>1.0</kd>
        <mu1>0.8</mu1>
        <mu2>0.8</mu2>
        <maxVel>0.0</maxVel>
        <minDepth>0.001</minDepth>
        <selfCollide>true</selfCollide>
    </gazebo>
    <transmission name="shoulder_pan_joint_trans">
        <type>transmission_interface/SimpleTransmission</type>
        <joint name="shoulder_pan_joint">
            <hardwareInterface>hardware_interface/EffortJointInterface</hardwareInterface>
        </joint>
        <actuator name="shoulder_pan_joint_motor">
            <mechanicalReduction>1</mechanicalReduction>
            <hardwareInterface>hardware_interface/EffortJointInterface</hardwareInterface>
        </actuator>
    </transmission>
    <transmission name="shoulder_lift_joint_trans">
        <type>transmission_interface/SimpleTransmission</type>
        <joint name="shoulder_lift_joint">
            <hardwareInterface>hardware_interface/EffortJointInterface</hardwareInterface>
        </joint>
        <actuator name="shoulder_lift_joint_motor">
            <mechanicalReduction>1</mechanicalReduction>
            <hardwareInterface>hardware_interface/EffortJointInterface</hardwareInterface>
        </actuator>
    </transmission>
    <transmission name="elbow_joint_trans">
        <type>transmission_interface/SimpleTransmission</type>
        <joint name="elbow_joint">
            <hardwareInterface>hardware_interface/EffortJointInterface</hardwareInterface>
        </joint>
        <actuator name="elbow_joint_motor">
            <mechanicalReduction>1</mechanicalReduction>
            <hardwareInterface>hardware_interface/EffortJointInterface</hardwareInterface>
        </actuator>
    </transmission>
    <transmission name="wrist_1_joint_trans">
        <type>transmission_interface/SimpleTransmission</type>
        <joint name="wrist_1_joint">
            <hardwareInterface>hardware_interface/EffortJointInterface</hardwareInterface>
        </joint>
        <actuator name="wrist_1_joint_motor">
            <mechanicalReduction>1</mechanicalReduction>
            <hardwareInterface>hardware_interface/EffortJointInterface</hardwareInterface>
        </actuator>
    </transmission>
    <transmission name="wrist_2_joint_trans">
        <type>transmission_interface/SimpleTransmission</type>
        <joint name="wrist_2_joint">
            <hardwareInterface>hardware_interface/EffortJointInterface</hardwareInterface>
        </joint>
        <actuator name="wrist_2_joint_motor">
            <mechanicalReduction>1</mechanicalReduction>
            <hardwareInterface>hardware_interface/EffortJointInterface</hardwareInterface>
        </actuator>
    </transmission>
    <transmission name="wrist_3_joint_trans">
        <type>transmission_interface/SimpleTransmission</type>
        <joint name="wrist_3_joint">
            <hardwareInterface>hardware_interface/EffortJointInterface</hardwareInterface>
        </joint>
        <actuator name="wrist_3_joint_motor">
            <mechanicalReduction>1</mechanicalReduction>
            <hardwareInterface>hardware_interface/EffortJointInterface</hardwareInterface>
        </actuator>
    </transmission>
    <gazebo reference="aubo_i5_base_link">
        <kp>1000000.0</kp>
        <kd>1.0</kd>
        <mu1>0.8</mu1>
        <mu2>0.8</mu2>
        <maxVel>0.0</maxVel>
        <minDepth>0.001</minDepth>
        <selfCollide>true</selfCollide>
    </gazebo>
    <gazebo reference="shoulder_link">
        <kp>1000000.0</kp>
        <kd>1.0</kd>
        <mu1>0.8</mu1>
        <mu2>0.8</mu2>
        <maxVel>0.0</maxVel>
        <minDepth>0.001</minDepth>
        <selfCollide>true</selfCollide>
    </gazebo>
    <gazebo reference="upper_arm_link">
        <kp>1000000.0</kp>
        <kd>1.0</kd>
        <mu1>0.8</mu1>
        <mu2>0.8</mu2>
        <maxVel>0.0</maxVel>
        <minDepth>0.001</minDepth>
        <selfCollide>true</selfCollide>
    </gazebo>
    <gazebo reference="forearm_link">
        <kp>1000000.0</kp>
        <kd>1.0</kd>
        <mu1>0.8</mu1>
        <mu2>0.8</mu2>
        <maxVel>0.0</maxVel>
        <minDepth>0.001</minDepth>
        <selfCollide>true</selfCollide>
    </gazebo>
    <gazebo reference="wrist_1_link">
        <kp>1000000.0</kp>
        <kd>1.0</kd>
        <mu1>0.8</mu1>
        <mu2>0.8</mu2>
        <maxVel>0.0</maxVel>
        <minDepth>0.001</minDepth>
        <selfCollide>true</selfCollide>
    </gazebo>
    <gazebo reference="wrist_2_link">
        <kp>1000000.0</kp>
        <kd>1.0</kd>
        <mu1>0.8</mu1>
        <mu2>0.8</mu2>
        <maxVel>0.0</maxVel>
        <minDepth>0.001</minDepth>
        <selfCollide>true</selfCollide>
    </gazebo>
    <gazebo reference="wrist_3_link">
        <kp>1000000.0</kp>
        <kd>1.0</kd>
        <mu1>0.8</mu1>
        <mu2>0.8</mu2>
        <maxVel>0.0</maxVel>
        <minDepth>0.001</minDepth>
        <selfCollide>true</selfCollide>
    </gazebo>
    <gazebo reference="shoulder_pan_joint">
        <kp>1000000.0</kp>
        <kd>1.0</kd>
        <mu1>0.8</mu1>
        <mu2>0.8</mu2>
        <maxVel>0.0</maxVel>
        <minDepth>0.001</minDepth>
        <selfCollide>true</selfCollide>
    </gazebo>
    <gazebo reference="shoulder_lift_joint">
        <kp>1000000.0</kp>
        <kd>1.0</kd>
        <mu1>0.8</mu1>
        <mu2>0.8</mu2>
        <maxVel>0.0</maxVel>
        <minDepth>0.001</minDepth>
        <selfCollide>true</selfCollide>
    </gazebo>
    <gazebo reference="elbow_joint">
        <kp>1000000.0</kp>
        <kd>1.0</kd>
        <mu1>0.8</mu1>
        <mu2>0.8</mu2>
        <maxVel>0.0</maxVel>
        <minDepth>0.001</minDepth>
        <selfCollide>true</selfCollide>
    </gazebo>
    <gazebo reference="wrist_1_joint">
        <kp>1000000.0</kp>
        <kd>1.0</kd>
        <mu1>0.8</mu1>
        <mu2>0.8</mu2>
        <maxVel>0.0</maxVel>
        <minDepth>0.001</minDepth>
        <selfCollide>true</selfCollide>
    </gazebo>
    <gazebo reference="wrist_2_joint">
        <kp>1000000.0</kp>
        <kd>1.0</kd>
        <mu1>0.8</mu1>
        <mu2>0.8</mu2>
        <maxVel>0.0</maxVel>
        <minDepth>0.001</minDepth>
        <selfCollide>true</selfCollide>
    </gazebo>
    <gazebo reference="wrist_3_joint">
        <kp>1000000.0</kp>
        <kd>1.0</kd>
        <mu1>0.8</mu1>
        <mu2>0.8</mu2>
        <maxVel>0.0</maxVel>
        <minDepth>0.001</minDepth>
        <selfCollide>true</selfCollide>
    </gazebo>
    <!-- LINKS -->
    <link name="aubo_i5_base_link">
        <inertial>
            <origin rpy="0 0 0" xyz="1.1888811586008421e-07 0.0015716172771383882 0.020944607206477398" />
            <mass value="0.83419" />
            <inertia ixx="0.0014368766488" ixy="-0.0" ixz="-0.0" iyy="0.00134804782337" iyz="-1.45914785287e-05" izz="0.00245533625101" />
        </inertial>
        <visual>
            <origin rpy="0 0 0" xyz="0 0 0" />
            <geometry>
                <mesh filename="package://aubo_description/meshes/aubo_i5/visual/base_link.DAE" />
            </geometry>
            <material name="">
                <color rgba="1 1 1 1" />
            </material>
        </visual>
        <collision>
            <origin rpy="0 0 0" xyz="0 0 0" />
            <geometry>
                <mesh filename="package://aubo_description/meshes/aubo_i5/collision/base_link.STL" />
            </geometry>
        </collision>
    </link>
    <link name="shoulder_link">
        <inertial>
            <origin rpy="0 0 0" xyz="0.0 0.006 -0.002" />
            <mass value="5.05" />
            <inertia ixx="0.0148" ixy="0" ixz="0" iyy="0.0143" iyz="-0.0" izz="0.0095" />
        </inertial>
        <visual>
            <origin rpy="0 0 0" xyz="0 0 0" />
            <geometry>
                <mesh filename="package://aubo_description/meshes/aubo_i5/visual/shoulder_Link.DAE" />
            </geometry>
            <material name="">
                <color rgba="1 1 1 1" />
            </material>
        </visual>
        <collision>
            <origin rpy="0 0 0" xyz="0 0 0" />
            <geometry>
                <mesh filename="package://aubo_description/meshes/aubo_i5/collision/shoulder_Link.STL" />
            </geometry>
        </collision>
    </link>
    <link name="upper_arm_link">
        <inertial>
            <origin rpy="0 0 0" xyz="0.20400000738607602 0.0003079721588177273 0.020108705518388777" />
            <mass value="11.90" />
            <inertia ixx="0.0293775827692" ixy="-0.0" ixz="0.0" iyy="0.340087312394" iyz="5.05037337668e-06" izz="0.33229261004" />
        </inertial>
        <visual>
            <origin rpy="0 0 0" xyz="0 0 0" />
            <geometry>
                <mesh filename="package://aubo_description/meshes/aubo_i5/visual/upperArm_Link.DAE" />
            </geometry>
            <material name="">
                <color rgba="1 1 1 1" />
            </material>
        </visual>
        <collision>
            <origin rpy="0 0 0" xyz="0 0 0" />
            <geometry>
                <mesh filename="package://aubo_description/meshes/aubo_i5/collision/upperArm_Link.STL" />
            </geometry>
        </collision>
    </link>
    <link name="forearm_link">
        <inertial>
            <origin rpy="0 0 0" xyz="0.18880713458962045 8.0702133231828e-06 0.09802927852704038" />
            <mass value="3.3" />
            <inertia ixx="0.00308093723552" ixy="2.43507928391e-06" ixz="-0.00106525352982" iyy="0.0646356206294" iyz="3.7462758214e-07" izz="0.0642559355749" />
        </inertial>
        <visual>
            <origin rpy="0 0 0" xyz="0 0 0" />
            <geometry>
                <mesh filename="package://aubo_description/meshes/aubo_i5/visual/foreArm_Link.DAE" />
            </geometry>
            <material name="">
                <color rgba="1 1 1 1" />
            </material>
        </visual>
        <collision>
            <origin rpy="0 0 0" xyz="0 0 0" />
            <geometry>
                <mesh filename="package://aubo_description/meshes/aubo_i5/collision/foreArm_Link.STL" />
            </geometry>
        </collision>
    </link>
    <link name="wrist_1_link">
        <inertial>
            <origin rpy="0 0 0" xyz="0.0 0.0028 -0.003" />
            <mass value="1.62" />
            <inertia ixx="0.0023" ixy="0" ixz="0" iyy="0.0013" iyz="0.0" izz="0.0022" />
        </inertial>
        <visual>
            <origin rpy="0 0 0" xyz="0 0 0" />
            <geometry>
                <mesh filename="package://aubo_description/meshes/aubo_i5/visual/wrist1_Link.DAE" />
            </geometry>
            <material name="">
                <color rgba="1 1 1 1" />
            </material>
        </visual>
        <collision>
            <origin rpy="0 0 0" xyz="0 0 0" />
            <geometry>
                <mesh filename="package://aubo_description/meshes/aubo_i5/collision/wrist1_Link.STL" />
            </geometry>
        </collision>
    </link>
    <link name="wrist_2_link">
        <inertial>
            <origin rpy="0 0 0" xyz="0.0 -0.0028 -0.003" />
            <mass value="1.62" />
            <inertia ixx="0.0023" ixy="0" ixz="0" iyy="0.0013" iyz="0.0" izz="0.0022" />
        </inertial>
        <visual>
            <origin rpy="0 0 0" xyz="0 0 0" />
            <geometry>
                <mesh filename="package://aubo_description/meshes/aubo_i5/visual/wrist2_Link.DAE" />
            </geometry>
            <material name="">
                <color rgba="1 1 1 1" />
            </material>
        </visual>
        <collision>
            <origin rpy="0 0 0" xyz="0 0 0" />
            <geometry>
                <mesh filename="package://aubo_description/meshes/aubo_i5/collision/wrist2_Link.STL" />
            </geometry>
        </collision>
    </link>
    <link name="wrist_3_link">
        <inertial>
            <origin rpy="0 0 0" xyz="3.8199537218366924e-05 -6.891283689656669e-05 -0.021357543727161605" />
            <mass value="0.399999999993" />
            <inertia ixx="0.000179519542885" ixy="-0.0" ixz="-0.0" iyy="0.000180837117512" iyz="0.0" izz="0.000268126436529" />
        </inertial>
        <visual>
            <origin rpy="0 0 0" xyz="0 0 0" />
            <geometry>
                <mesh filename="package://aubo_description/meshes/aubo_i5/visual/wrist3_Link.DAE" />
            </geometry>
            <material name="">
                <color rgba="1 1 1 1" />
            </material>
        </visual>
        <collision>
            <origin rpy="0 0 0" xyz="0 0 0" />
            <geometry>
                <mesh filename="package://aubo_description/meshes/aubo_i5/collision/wrist3_Link.STL" />
            </geometry>
        </collision>
    </link>
    <!-- JOINTS -->
    <joint name="shoulder_pan_joint" type="revolute">
        <origin rpy="0 0 3.1416" xyz="0 0 0.122" />
        <parent link="aubo_i5_base_link" />
        <child link="shoulder_link" />
        <axis xyz="0 0 1" />
        <limit effort="150" lower="-3.04" upper="3.04" velocity="3.14159265359" />
    </joint>
    <joint name="shoulder_lift_joint" type="revolute">
        <origin rpy="-1.5708 -1.5708 0" xyz="0 0.1215 0" />
        <parent link="shoulder_link" />
        <child link="upper_arm_link" />
        <axis xyz="0 0 1" />
        <limit effort="150" lower="-3.04" upper="3.04" velocity="3.14159265359" />
    </joint>
    <joint name="elbow_joint" type="revolute">
        <origin rpy="-3.1416 -5.1632E-18 -5.459E-16" xyz="0.408 0 0" />
        <parent link="upper_arm_link" />
        <child link="forearm_link" />
        <axis xyz="0 0 1" />
        <limit effort="150" lower="-3.04" upper="3.04" velocity="3.14159265359" />
    </joint>
    <joint name="wrist_1_joint" type="revolute">
        <origin rpy="3.1416 -1.8323E-15 1.5708" xyz="0.376 0 0" />
        <parent link="forearm_link" />
        <child link="wrist_1_link" />
        <axis xyz="0 0 1" />
        <limit effort="28" lower="-3.04" upper="3.04" velocity="3.14159265359" />
    </joint>
    <joint name="wrist_2_joint" type="revolute">
        <origin rpy="-1.5708 -1.8709E-15 -1.6653E-16" xyz="0 0.1025 0" />
        <parent link="wrist_1_link" />
        <child link="wrist_2_link" />
        <axis xyz="0 0 1" />
        <limit effort="28" lower="-3.04" upper="3.04" velocity="3.14159265359" />
    </joint>
    <joint name="wrist_3_joint" type="revolute">
        <origin rpy="1.5708 0 1.7907E-15" xyz="0 -0.094 0" />
        <parent link="wrist_2_link" />
        <child link="wrist_3_link" />
        <axis xyz="0 0 1" />
        <limit effort="28" lower="-3.04" upper="3.04" velocity="3.14159265359" />
    </joint>
    <link name="ee_link">
        <collision>
            <geometry>
                <box size="0.01 0.01 0.01" />
            </geometry>
            <origin rpy="0 0 0" xyz="-0.01 0 0" />
        </collision>
        <inertial>
            <mass value="0.1" />
            <origin xyz="0 0 0" rpy="0 0 0" />
            <inertia ixx="0.03" iyy="0.03" izz="0.03" ixy="0.0" ixz="0.0" iyz="0.0" />
        </inertial>
    </link>
    <joint name="ee_fixed_joint" type="fixed">
        <parent link="wrist_3_link" />
        <child link="ee_link" />
        <origin rpy="3.14159265359 -1.57079632679 1.57079632679" xyz="0.0 0.0 0.0" />
    </joint>
    <joint name="aubo_i5_base_joint" type="fixed">
        <parent link="arm_mount_1" />
        <child link="aubo_i5_base_link" />
        <origin rpy="0 0 0" xyz="0 0 0" />
    </joint>
    <transmission name="left_outer_knuckle_joint_trans">
        <type>transmission_interface/SimpleTransmission</type>
        <joint name="left_outer_knuckle_joint">
            <hardwareInterface>hardware_interface/EffortJointInterface</hardwareInterface>
        </joint>
        <actuator name="left_outer_knuckle_joint_motor">
            <mechanicalReduction>1</mechanicalReduction>
            <hardwareInterface>hardware_interface/EffortJointInterface</hardwareInterface>
        </actuator>
    </transmission>
    <!-- Mimic joint plugin -->
    <gazebo>
        <plugin filename="libroboticsgroup_upatras_gazebo_mimic_joint_plugin.so" name="mimic_dh_robotics_ag95_3">
            <joint>left_outer_knuckle_joint</joint>
            <mimicJoint>right_outer_knuckle_joint</mimicJoint>
            <multiplier>1</multiplier>
            <hasPID />
        </plugin>
    </gazebo>
    <gazebo reference="ag95_base_link">
        <material>Gazebo/Grey</material>
        <kp>1000000.0</kp>
        <kd>1.0</kd>
        <mu1>1.16</mu1>
        <mu2>1.16</mu2>
        <maxVel>0.0</maxVel>
        <minDepth>0.003</minDepth>
    </gazebo>
    <gazebo reference="ag95_body">
        <material>Gazebo/Black</material>
        <kp>1000000.0</kp>
        <kd>1.0</kd>
        <mu1>1.16</mu1>
        <mu2>1.16</mu2>
        <maxVel>0.0</maxVel>
        <minDepth>0.003</minDepth>
    </gazebo>
    <gazebo reference="left_outer_knuckle">
        <material>Gazebo/Black</material>
        <kp>1000000.0</kp>
        <kd>1.0</kd>
        <mu1>1.16</mu1>
        <mu2>1.16</mu2>
        <maxVel>0.0</maxVel>
        <minDepth>0.003</minDepth>
    </gazebo>
    <gazebo reference="left_inner_knuckle">
        <material>Gazebo/Black</material>
        <kp>1000000.0</kp>
        <kd>1.0</kd>
        <mu1>1.16</mu1>
        <mu2>1.16</mu2>
        <maxVel>0.0</maxVel>
        <minDepth>0.003</minDepth>
    </gazebo>
    <gazebo reference="left_finger">
        <material>Gazebo/Grey</material>
        <kp>1000000.0</kp>
        <kd>1.0</kd>
        <mu1>1.16</mu1>
        <mu2>1.16</mu2>
        <maxVel>0.0</maxVel>
        <minDepth>0.003</minDepth>
    </gazebo>
    <gazebo reference="right_outer_knuckle">
        <material>Gazebo/Black</material>
        <kp>1000000.0</kp>
        <kd>1.0</kd>
        <mu1>1.16</mu1>
        <mu2>1.16</mu2>
        <maxVel>0.0</maxVel>
        <minDepth>0.003</minDepth>
    </gazebo>
    <gazebo reference="right_inner_knuckle">
        <material>Gazebo/Black</material>
        <kp>1000000.0</kp>
        <kd>1.0</kd>
        <mu1>1.16</mu1>
        <mu2>1.16</mu2>
        <maxVel>0.0</maxVel>
        <minDepth>0.003</minDepth>
    </gazebo>
    <gazebo reference="right_finger">
        <material>Gazebo/Grey</material>
        <kp>1000000.0</kp>
        <kd>1.0</kd>
        <mu1>1.16</mu1>
        <mu2>1.16</mu2>
        <maxVel>0.0</maxVel>
        <minDepth>0.003</minDepth>
    </gazebo>
    <gazebo reference="left_outer_knuckle_joint">
        <implicitSpringDamper>true</implicitSpringDamper>
    </gazebo>
    <gazebo reference="left_finger_joint">
        <implicitSpringDamper>true</implicitSpringDamper>
    </gazebo>
    <gazebo reference="left_inner_knuckle_joint">
        <implicitSpringDamper>true</implicitSpringDamper>
    </gazebo>
    <gazebo reference="left_inner_knuckle_to_finger_joint">
        <implicitSpringDamper>true</implicitSpringDamper>
    </gazebo>
    <gazebo reference="right_outer_knuckle_joint">
        <implicitSpringDamper>true</implicitSpringDamper>
    </gazebo>
    <gazebo reference="right_finger_joint">
        <implicitSpringDamper>true</implicitSpringDamper>
    </gazebo>
    <gazebo reference="right_inner_knuckle_joint">
        <implicitSpringDamper>true</implicitSpringDamper>
    </gazebo>
    <gazebo reference="right_inner_knuckle_to_finger_joint">
        <implicitSpringDamper>true</implicitSpringDamper>
    </gazebo>
    <!-- base link flange -->
    <link name="ag95_base_link">
        <inertial>
            <origin rpy="0 0 0" xyz="7.892486664218268e-13 9.73814800116557e-05 0.0030311891257515876" />
            <mass value="0.18321316702693136" />
            <inertia ixx="4e-05" ixy="0.0" ixz="-0.0" iyy="0.000121" iyz="0.0" izz="0.000158" />
        </inertial>
        <visual>
            <origin rpy="0 0 0" xyz="0 0 0" />
            <geometry>
                <mesh filename="package://dh_ag95_description/meshes/visual/base_link.stl" scale="0.001 0.001 0.001" />
            </geometry>
            <material name="">
                <color rgba="0.792156862745098 0.819607843137255 0.933333333333333 1" />
            </material>
        </visual>
        <collision>
            <origin rpy="0 0 0" xyz="0 0 0" />
            <geometry>
                <mesh filename="package://dh_ag95_description/meshes/collision/base_link.stl" scale="0.001 0.001 0.001" />
            </geometry>
        </collision>
    </link>
    <!-- main body of gripper -->
    <link name="ag95_body">
        <inertial>
            <origin rpy="0 0 0" xyz="0.040363309423792425 0.014263796342398428 0.04377145101823153" />
            <mass value="2.681074820833332" />
            <inertia ixx="0.003857" ixy="-3e-06" ixz="-9e-06" iyy="0.004463" iyz="-2e-06" izz="0.001562" />
        </inertial>
        <visual>
            <origin rpy="0 0 0" xyz="0.0405 0.0143 -0.0147" />
            <geometry>
                <mesh filename="package://dh_ag95_description/meshes/visual/gripper_body.stl" scale="0.001 0.001 0.001" />
            </geometry>
            <material name="">
                <color rgba="0.1 0.1 0.1 1" />
            </material>
        </visual>
        <collision>
            <origin rpy="0 0 0" xyz="0.0405 0.0143 -0.0147" />
            <geometry>
                <mesh filename="package://dh_ag95_description/meshes/collision/gripper_body.stl" scale="0.001 0.001 0.001" />
            </geometry>
        </collision>
    </link>
    <joint name="ag95_body_joint" type="fixed">
        <origin rpy="0 0 0" xyz="-0.0405 -0.0143 0.0147" />
        <parent link="ag95_base_link" />
        <child link="ag95_body" />
    </joint>
    <link name="left_outer_knuckle">
        <inertial>
            <origin rpy="0 0 0" xyz="0.027678515816713697 0.008750002359538555 -4.432690447753185e-07" />
            <mass value="0.0589066057773107" />
            <inertia ixx="1e-06" ixy="0.0" ixz="-0.0" iyy="1.7e-05" iyz="0.0" izz="1.7e-05" />
        </inertial>
        <visual>
            <origin rpy="0 0 0" xyz="-0.036673 0.00875 -0.098336" />
            <geometry>
                <mesh filename="package://dh_ag95_description/meshes/visual/outer_knuckle.stl" scale="0.001 0.001 0.001" />
            </geometry>
            <material name="">
                <color rgba="0.1 0.1 0.1 1" />
            </material>
        </visual>
        <collision>
            <origin rpy="0 0 0" xyz="-0.036673 0.00875 -0.098336" />
            <geometry>
                <mesh filename="package://dh_ag95_description/meshes/collision/outer_knuckle.stl" scale="0.001 0.001 0.001" />
            </geometry>
        </collision>
    </link>
    <link name="left_inner_knuckle">
        <inertial>
            <origin rpy="0 0 0" xyz="-0.001773347637755853 0.025399999999162655 0.028950024725163018" />
            <mass value="0.07116672022913799" />
            <inertia ixx="3.7e-05" ixy="0.0" ixz="0.0" iyy="1.7e-05" iyz="-0.0" izz="2.1e-05" />
        </inertial>
        <visual>
            <origin rpy="0 0 0" xyz="-0.016 0.0254 -0.10586" />
            <geometry>
                <mesh filename="package://dh_ag95_description/meshes/visual/inner_knuckle.stl" scale="0.001 0.001 0.001" />
            </geometry>
            <material name="">
                <color rgba="0.1 0.1 0.1 1" />
            </material>
        </visual>
        <collision>
            <origin rpy="0 0 0" xyz="-0.016 0.0254 -0.10586" />
            <geometry>
                <mesh filename="package://dh_ag95_description/meshes/collision/inner_knuckle.stl" scale="0.001 0.001 0.001" />
            </geometry>
        </collision>
    </link>
    <link name="left_finger">
        <inertial>
            <origin rpy="0 0 0" xyz="-0.013763205176003518 0.008750002316393751 0.007315452388518454" />
            <mass value="0.035304126564626004" />
            <inertia ixx="2e-06" ixy="0.0" ixz="1e-06" iyy="4e-06" iyz="-0.0" izz="3e-06" />
        </inertial>
        <visual>
            <origin rpy="0 0 0" xyz="-0.091673 0.00875 -0.098336" />
            <geometry>
                <mesh filename="package://dh_ag95_description/meshes/visual/finger.stl" scale="0.001 0.001 0.001" />
            </geometry>
            <material name="">
                <color rgba="0.1 0.1 0.1 1" />
            </material>
        </visual>
        <collision>
            <origin rpy="0 0 0" xyz="-0.091673 0.00875 -0.098336" />
            <geometry>
                <mesh filename="package://dh_ag95_description/meshes/collision/finger.stl" scale="0.001 0.001 0.001" />
            </geometry>
        </collision>
    </link>
    <link name="left_finger_pad">
        <inertial>
            <origin rpy="0 0 0" xyz="-0.0022695421476374017 2.3166990085415594e-09 0.00779073905191241" />
            <mass value="0.047823655444711066" />
            <inertia ixx="5e-06" ixy="-0.0" ixz="0.0" iyy="4e-06" iyz="0.0" izz="2e-06" />
        </inertial>
        <visual>
            <origin rpy="0 0 0" xyz="-0.0705 -0.0 -0.12056" />
            <geometry>
                <mesh filename="package://dh_ag95_description/meshes/visual/finger_pad.stl" scale="0.001 0.001 0.001" />
            </geometry>
            <material name="">
                <color rgba="0.792156862745098 0.819607843137255 0.933333333333333 1" />
            </material>
        </visual>
        <collision>
            <origin rpy="0 0 0" xyz="-0.0705 -0.0 -0.12056" />
            <geometry>
                <mesh filename="package://dh_ag95_description/meshes/collision/finger_pad.stl" scale="0.001 0.001 0.001" />
            </geometry>
        </collision>
    </link>
    <joint name="left_finger_joint" type="revolute">
        <origin rpy="0 0.780005096009 0" xyz="0.055 0.0 0.0" />
        <parent link="left_outer_knuckle" />
        <child link="left_finger" />
        <axis xyz="0.0 1.0 -0.0" />
        <limit effort="10.0" lower="-0.01" upper="0.94" velocity="1.0" />
        <mimic joint="left_outer_knuckle_joint" multiplier="1" offset="0" />
    </joint>
    <joint name="left_inner_knuckle_joint" type="revolute">
        <origin rpy="0 0.790791230786 0.0" xyz="0.0565 -0.0111 0.09116" />
        <parent link="ag95_body" />
        <child link="left_inner_knuckle" />
        <axis xyz="0.0 -1.0 -0.0" />
        <limit effort="10.0" lower="-0.01" upper="0.94" velocity="1.0" />
        <mimic joint="left_outer_knuckle_joint" multiplier="1" offset="0" />
    </joint>
    <!-- This joint closes the kinematic loop. Since loops are not allowed in URDF, but they are
      allowed in SDF, this is an SDF fragment. -->
    <gazebo>
        <joint name="left_inner_knuckle_to_finger_joint" type="revolute">
            <pose>-0.020673 0 0.007524 0 0 0</pose>
            <axis>
                <xyz>0 1 0</xyz>
                <use_parent_model_frame>false</use_parent_model_frame>
            </axis>
            <parent>left_inner_knuckle</parent>
            <child>left_finger</child>
        </joint>
    </gazebo>
    <joint name="left_inner_finger_pad_joint" type="fixed">
        <origin rpy="0 0 0" xyz="-0.021173 0.00875 0.022224" />
        <parent link="left_finger" />
        <child link="left_finger_pad" />
    </joint>
    <joint name="left_outer_knuckle_joint" type="revolute">
        <origin rpy="0 -0.780005096009 0" xyz="0.077173 0.00555 0.083636" />
        <parent link="ag95_body" />
        <child link="left_outer_knuckle" />
        <axis xyz="-0.0 -1.0 0.0" />
        <limit effort="10.0" lower="0" upper="0.93" velocity="1.0" />
    </joint>
    <joint name="right_finger_joint" type="revolute">
        <origin rpy="0 0.780005096009 0" xyz="0.055 0.0 0.0" />
        <parent link="right_outer_knuckle" />
        <child link="right_finger" />
        <axis xyz="0.0 1.0 -0.0" />
        <limit effort="10.0" lower="-0.01" upper="0.94" velocity="1.0" />
        <mimic joint="left_outer_knuckle_joint" multiplier="1" offset="0" />
    </joint>
    <joint name="right_inner_knuckle_joint" type="revolute">
        <origin rpy="0 0.790791230786 -3.14159265359" xyz="0.0245 0.0397 0.09116" />
        <parent link="ag95_body" />
        <child link="right_inner_knuckle" />
        <axis xyz="0.0 -1.0 -0.0" />
        <limit effort="10.0" lower="-0.01" upper="0.94" velocity="1.0" />
        <mimic joint="left_outer_knuckle_joint" multiplier="1" offset="0" />
    </joint>
    <!-- This joint closes the kinematic loop. Since loops are not allowed in URDF, but they are
      allowed in SDF, this is an SDF fragment. -->
    <gazebo>
        <joint name="right_inner_knuckle_to_finger_joint" type="revolute">
            <pose>-0.020673 0 0.007524 0 0 0</pose>
            <axis>
                <xyz>0 1 0</xyz>
                <use_parent_model_frame>false</use_parent_model_frame>
            </axis>
            <parent>right_inner_knuckle</parent>
            <child>right_finger</child>
        </joint>
    </gazebo>
    <joint name="right_inner_finger_pad_joint" type="fixed">
        <origin rpy="0 0 0" xyz="-0.021173 0.00875 0.022224" />
        <parent link="right_finger" />
        <child link="right_finger_pad" />
    </joint>
    <link name="right_outer_knuckle">
        <inertial>
            <origin rpy="0 0 0" xyz="0.027678515816713697 0.008750002359538555 -4.432690447753185e-07" />
            <mass value="0.0589066057773107" />
            <inertia ixx="1e-06" ixy="0.0" ixz="-0.0" iyy="1.7e-05" iyz="0.0" izz="1.7e-05" />
        </inertial>
        <visual>
            <origin rpy="0 0 0" xyz="-0.036673 0.00875 -0.098336" />
            <geometry>
                <mesh filename="package://dh_ag95_description/meshes/visual/outer_knuckle.stl" scale="0.001 0.001 0.001" />
            </geometry>
            <material name="">
                <color rgba="0.1 0.1 0.1 1" />
            </material>
        </visual>
        <collision>
            <origin rpy="0 0 0" xyz="-0.036673 0.00875 -0.098336" />
            <geometry>
                <mesh filename="package://dh_ag95_description/meshes/collision/outer_knuckle.stl" scale="0.001 0.001 0.001" />
            </geometry>
        </collision>
    </link>
    <link name="right_inner_knuckle">
        <inertial>
            <origin rpy="0 0 0" xyz="-0.001773347637755853 0.025399999999162655 0.028950024725163018" />
            <mass value="0.07116672022913799" />
            <inertia ixx="3.7e-05" ixy="0.0" ixz="0.0" iyy="1.7e-05" iyz="-0.0" izz="2.1e-05" />
        </inertial>
        <visual>
            <origin rpy="0 0 0" xyz="-0.016 0.0254 -0.10586" />
            <geometry>
                <mesh filename="package://dh_ag95_description/meshes/visual/inner_knuckle.stl" scale="0.001 0.001 0.001" />
            </geometry>
            <material name="">
                <color rgba="0.1 0.1 0.1 1" />
            </material>
        </visual>
        <collision>
            <origin rpy="0 0 0" xyz="-0.016 0.0254 -0.10586" />
            <geometry>
                <mesh filename="package://dh_ag95_description/meshes/collision/inner_knuckle.stl" scale="0.001 0.001 0.001" />
            </geometry>
        </collision>
    </link>
    <link name="right_finger">
        <inertial>
            <origin rpy="0 0 0" xyz="-0.013763205176003518 0.008750002316393751 0.007315452388518454" />
            <mass value="0.035304126564626004" />
            <inertia ixx="2e-06" ixy="0.0" ixz="1e-06" iyy="4e-06" iyz="-0.0" izz="3e-06" />
        </inertial>
        <visual>
            <origin rpy="0 0 0" xyz="-0.091673 0.00875 -0.098336" />
            <geometry>
                <mesh filename="package://dh_ag95_description/meshes/visual/finger.stl" scale="0.001 0.001 0.001" />
            </geometry>
            <material name="">
                <color rgba="0.1 0.1 0.1 1" />
            </material>
        </visual>
        <collision>
            <origin rpy="0 0 0" xyz="-0.091673 0.00875 -0.098336" />
            <geometry>
                <mesh filename="package://dh_ag95_description/meshes/collision/finger.stl" scale="0.001 0.001 0.001" />
            </geometry>
        </collision>
    </link>
    <link name="right_finger_pad">
        <inertial>
            <origin rpy="0 0 0" xyz="-0.0022695421476374017 2.3166990085415594e-09 0.00779073905191241" />
            <mass value="0.047823655444711066" />
            <inertia ixx="5e-06" ixy="-0.0" ixz="0.0" iyy="4e-06" iyz="0.0" izz="2e-06" />
        </inertial>
        <visual>
            <origin rpy="0 0 0" xyz="-0.0705 -0.0 -0.12056" />
            <geometry>
                <mesh filename="package://dh_ag95_description/meshes/visual/finger_pad.stl" scale="0.001 0.001 0.001" />
            </geometry>
            <material name="">
                <color rgba="0.792156862745098 0.819607843137255 0.933333333333333 1" />
            </material>
        </visual>
        <collision>
            <origin rpy="0 0 0" xyz="-0.0705 -0.0 -0.12056" />
            <geometry>
                <mesh filename="package://dh_ag95_description/meshes/collision/finger_pad.stl" scale="0.001 0.001 0.001" />
            </geometry>
        </collision>
    </link>
    <joint name="right_outer_knuckle_joint" type="revolute">
        <origin rpy="0 -0.780005096009 3.14159265359" xyz="0.003827 0.02305 0.083636" />
        <parent link="ag95_body" />
        <child link="right_outer_knuckle" />
        <axis xyz="-0.0 -1.0 0.0" />
        <limit effort="10.0" lower="-0.01" upper="0.94" velocity="1.0" />
        <mimic joint="left_outer_knuckle_joint" multiplier="1" offset="0" />
    </joint>
    <joint name="gripper_base_joint" type="fixed">
        <parent link="ee_link" />
        <child link="ag95_base_link" />
        <origin rpy="1.57079632679  3.14159265359 1.57079632679" xyz="0 0 0" />
    </joint>
    <link name="arm_mount_1">
        <inertial>
            <origin rpy="0 0 0" xyz="7.105427357601002e-17 -7.105427357601002e-17 -0.013621546881" />
            <mass value="1.9541243164872064" />
            <inertia ixx="0.007781" ixy="0.0" ixz="-0.0" iyy="0.007781" iyz="-0.0" izz="0.01542" />
        </inertial>
        <visual>
            <origin rpy="0 0 0" xyz="0 0 -0.0225" />
            <geometry>
                <mesh filename="package://lara_description/meshes/workspace/arm_mount.stl" scale="0.001 0.001 0.001" />
            </geometry>
            <material name="aluminum" />
        </visual>
        <collision>
            <origin rpy="0 0 0" xyz="0 0 -0.0225" />
            <geometry>
                <mesh filename="package://lara_description/meshes/workspace/arm_mount.stl" scale="0.001 0.001 0.001" />
            </geometry>
        </collision>
    </link>
    <link name="arm_mount_2">
        <inertial>
            <origin rpy="0 0 0" xyz="7.105427357601002e-17 -7.105427357601002e-17 -0.013621546881" />
            <mass value="1.9541243164872064" />
            <inertia ixx="0.007781" ixy="0.0" ixz="-0.0" iyy="0.007781" iyz="-0.0" izz="0.01542" />
        </inertial>
        <visual>
            <origin rpy="0 0 0" xyz="0 0 -0.0225" />
            <geometry>
                <mesh filename="package://lara_description/meshes/workspace/arm_mount.stl" scale="0.001 0.001 0.001" />
            </geometry>
            <material name="aluminum" />
        </visual>
        <collision>
            <origin rpy="0 0 0" xyz="0 0 -0.0225" />
            <geometry>
                <mesh filename="package://lara_description/meshes/workspace/arm_mount.stl" scale="0.001 0.001 0.001" />
            </geometry>
        </collision>
    </link>
    <link name="base_mount">
        <inertial>
            <origin rpy="0 0 0" xyz="-0.667374581686 0.9 0.021576490144779893" />
            <mass value="32.0586863751" />
            <inertia ixx="11.053198" ixy="0.0" ixz="0.0054995" iyy="1.081206" iyz="-0.0" izz="12.123644" />
        </inertial>
        <visual>
            <origin rpy="0 0 0" xyz="-.341 .8775 0" />
            <geometry>
                <mesh filename="package://lara_description/meshes/workspace/base_mount.stl" scale="0.001 0.001 0.001" />
            </geometry>
            <material name="aluminum" />
        </visual>
        <collision>
            <origin rpy="0 0 0" xyz="-.341 .8775 0" />
            <geometry>
                <mesh filename="package://lara_description/meshes/workspace/base_mount.stl" scale="0.001 0.001 0.001" />
            </geometry>
        </collision>
    </link>
    <link name="table">
        <inertial>
            <origin rpy="0 0 0" xyz="3.206702352856439e-16 -7.90986580371255e-15 0.6742624735551555" />
            <mass value="71.0972647844" />
            <inertia ixx="35.6234895" ixy="-0.0" ixz="-0.0" iyy="11.9473935" iyz="-0.0" izz="43.8528735" />
        </inertial>
        <visual>
            <origin rpy="0 0 0" xyz="0 0 0" />
            <geometry>
                <mesh filename="package://lara_description/meshes/workspace/table.stl" scale="0.001 0.001 0.001" />
            </geometry>
            <material name="wood" />
        </visual>
        <collision>
            <origin rpy="0 0 0" xyz="0 0 0" />
            <geometry>
                <mesh filename="package://lara_description/meshes/workspace/table.stl" scale="0.001 0.001 0.001" />
            </geometry>
        </collision>
    </link>
    <joint name="arm_mount_1_joint" type="fixed">
        <parent link="base_mount" />
        <child link="arm_mount_1" />
        <origin xyz="-.7465 0.5 0.0675" />
    </joint>
    <!-- mount spacing -->
    <joint name="arm_mount_2_joint" type="fixed">
        <parent link="base_mount" />
        <child link="arm_mount_2" />
        <origin xyz="-.7465 1.3 0.0675" />
    </joint>
    <joint name="base_mount_joint" type="fixed">
        <parent link="table" />
        <child link="base_mount" />
        <origin xyz=".4295 -.9 .750" />
    </joint>
    <joint name="table_joint" type="fixed">
        <parent link="world" />
        <child link="table" />
        <origin rpy="0 0 0" xyz="0 0 0" />
    </joint>
    <!-- <sensor_d435 parent="world" name="camera1" publish_pointcloud="false" topics_ns="camera1">
    <origin xyz=".75 -0.4 1.5" rpy="0 ${pi/4} ${pi}"/>
  </sensor_d435>

  <sensor_d435 parent="world" name="camera2" publish_pointcloud="false" topics_ns="camera2">
    <origin xyz="0 1 1.2" rpy="0 0 ${-pi/2}"/>
  </sensor_d435> -->
    <!-- Add an additional link to plan with. Oriented like the aubo_i5 ee_link frame. -->
    <link name="gripper_tip_link" />
    <joint name="gripper_tip_link_joint" type="fixed">
        <parent link="ee_link" />
        <child link="gripper_tip_link" />
        <origin rpy="0 0 0" xyz="0.2 0 0" />
    </joint>
    <!-- Add an additional link to teleop control with Meta Quest 2 controller. Oriented like the Meta
  Quest 2 controller frame -->
    <link name="teleop_link" />
    <joint name="teleop_link_joint" type="fixed">
        <parent link="gripper_tip_link" />
        <child link="teleop_link" />
        <origin rpy="-1.57079632679 0 -1.57079632679" xyz="0 0 0" />
    </joint>
    <!-- Add an additional frame to plan with. Oriented like world frame. -->
    <link name="manipulation_frame" />
    <joint name="manipulation_frame_joint" type="fixed">
        <parent link="aubo_i5_base_link" />
        <child link="manipulation_frame" />
        <origin rpy="0 0 0" xyz="0 0 -0.0675" />
    </joint>
    <!-- world link for gazebo -->
    <link name="world" />
    <!-- ros_control plugin -->
    <gazebo>
        <plugin filename="libgazebo_ros_control.so" name="gazebo_ros_control" />
    </gazebo>
    <!-- gazebo grasp plugin -->
    <gazebo>
        <plugin filename="libgazebo_grasp_fix.so" name="gazebo_grasp_fix">
            <arm>
                <arm_name>aubo_i5_ag95</arm_name>
                <palm_link>wrist_3_link</palm_link>
                <gripper_link>left_finger</gripper_link>
                <gripper_link>right_finger</gripper_link>
                <gripper_link>left_inner_knuckle</gripper_link>
                <gripper_link>right_inner_knuckle</gripper_link>
            </arm>
            <forces_angle_tolerance>90</forces_angle_tolerance>
            <update_rate>30</update_rate>
            <grip_count_threshold>1</grip_count_threshold>
            <max_grip_count>3</max_grip_count>
            <release_tolerance>0.004</release_tolerance>
            <disable_collisions_on_attach>false</disable_collisions_on_attach>
            <contact_topic>__default_topic__</contact_topic>
        </plugin>
    </gazebo>
    <transmission name="trans_left_finger_joint">
        <type>transmission_interface/SimpleTransmission</type>
        <joint name="left_finger_joint">
            <hardwareInterface>hardware_interface/EffortJointInterface</hardwareInterface>
        </joint>
        <actuator name="left_finger_joint_motor">
            <hardwareInterface>hardware_interface/EffortJointInterface</hardwareInterface>
            <mechanicalReduction>1</mechanicalReduction>
        </actuator>
    </transmission>
    <transmission name="trans_left_inner_knuckle_joint">
        <type>transmission_interface/SimpleTransmission</type>
        <joint name="left_inner_knuckle_joint">
            <hardwareInterface>hardware_interface/EffortJointInterface</hardwareInterface>
        </joint>
        <actuator name="left_inner_knuckle_joint_motor">
            <hardwareInterface>hardware_interface/EffortJointInterface</hardwareInterface>
            <mechanicalReduction>1</mechanicalReduction>
        </actuator>
    </transmission>
    <transmission name="trans_right_finger_joint">
        <type>transmission_interface/SimpleTransmission</type>
        <joint name="right_finger_joint">
            <hardwareInterface>hardware_interface/EffortJointInterface</hardwareInterface>
        </joint>
        <actuator name="right_finger_joint_motor">
            <hardwareInterface>hardware_interface/EffortJointInterface</hardwareInterface>
            <mechanicalReduction>1</mechanicalReduction>
        </actuator>
    </transmission>
    <transmission name="trans_right_inner_knuckle_joint">
        <type>transmission_interface/SimpleTransmission</type>
        <joint name="right_inner_knuckle_joint">
            <hardwareInterface>hardware_interface/EffortJointInterface</hardwareInterface>
        </joint>
        <actuator name="right_inner_knuckle_joint_motor">
            <hardwareInterface>hardware_interface/EffortJointInterface</hardwareInterface>
            <mechanicalReduction>1</mechanicalReduction>
        </actuator>
    </transmission>
    <transmission name="trans_right_outer_knuckle_joint">
        <type>transmission_interface/SimpleTransmission</type>
        <joint name="right_outer_knuckle_joint">
            <hardwareInterface>hardware_interface/EffortJointInterface</hardwareInterface>
        </joint>
        <actuator name="right_outer_knuckle_joint_motor">
            <hardwareInterface>hardware_interface/EffortJointInterface</hardwareInterface>
            <mechanicalReduction>1</mechanicalReduction>
        </actuator>
    </transmission>
</robot>

